[2023-07-25T20:16:15.685-0300] {taskinstance.py:1103} INFO - Dependencies all met for dep_context=non-requeueable deps ti=<TaskInstance: LH_ED_GABRIELLEMUNIZ.write_second_db scheduled__2023-07-25T13:45:00+00:00 [queued]>
[2023-07-25T20:16:15.692-0300] {taskinstance.py:1103} INFO - Dependencies all met for dep_context=requeueable deps ti=<TaskInstance: LH_ED_GABRIELLEMUNIZ.write_second_db scheduled__2023-07-25T13:45:00+00:00 [queued]>
[2023-07-25T20:16:15.693-0300] {taskinstance.py:1308} INFO - Starting attempt 36 of 38
[2023-07-25T20:16:15.711-0300] {taskinstance.py:1327} INFO - Executing <Task(PythonOperator): write_second_db> on 2023-07-25 13:45:00+00:00
[2023-07-25T20:16:15.716-0300] {standard_task_runner.py:57} INFO - Started process 150074 to run task
[2023-07-25T20:16:15.720-0300] {standard_task_runner.py:84} INFO - Running: ['airflow', 'tasks', 'run', 'LH_ED_GABRIELLEMUNIZ', 'write_second_db', 'scheduled__2023-07-25T13:45:00+00:00', '--job-id', '259', '--raw', '--subdir', 'DAGS_FOLDER/LH_ED_GABRIELLEMUNIZ.py', '--cfg-path', '/tmp/tmprzoskvan']
[2023-07-25T20:16:15.720-0300] {standard_task_runner.py:85} INFO - Job 259: Subtask write_second_db
[2023-07-25T20:16:15.766-0300] {task_command.py:410} INFO - Running <TaskInstance: LH_ED_GABRIELLEMUNIZ.write_second_db scheduled__2023-07-25T13:45:00+00:00 [running]> on host ubuntu
[2023-07-25T20:16:15.837-0300] {taskinstance.py:1545} INFO - Exporting env vars: AIRFLOW_CTX_DAG_OWNER='gabi' AIRFLOW_CTX_DAG_ID='LH_ED_GABRIELLEMUNIZ' AIRFLOW_CTX_TASK_ID='write_second_db' AIRFLOW_CTX_EXECUTION_DATE='2023-07-25T13:45:00+00:00' AIRFLOW_CTX_TRY_NUMBER='36' AIRFLOW_CTX_DAG_RUN_ID='scheduled__2023-07-25T13:45:00+00:00'
[2023-07-25T20:16:15.872-0300] {logging_mixin.py:150} WARNING - /home/gabi/Documentos/Gabi/Indicium/code-challenge-indicium/dags/LH_ED_GABRIELLEMUNIZ.py:82 UserWarning: pandas only supports SQLAlchemy connectable (engine/connection) or database string URI or sqlite3 DBAPI2 connection. Other DBAPI2 objects are not tested. Please consider using SQLAlchemy.
[2023-07-25T20:16:15.874-0300] {taskinstance.py:1824} ERROR - Task failed with exception
Traceback (most recent call last):
  File "/home/gabi/Documentos/Gabi/Indicium/code-challenge-indicium/ind_env/lib/python3.10/site-packages/pandas/io/sql.py", line 2202, in execute
    cur.execute(sql, *args)
psycopg2.errors.SyntaxError: syntax error at or near ";"
LINE 1: ...ELECT name FROM sqlite_master WHERE type='table' AND name=?;
                                                                      ^


The above exception was the direct cause of the following exception:

Traceback (most recent call last):
  File "/home/gabi/Documentos/Gabi/Indicium/code-challenge-indicium/ind_env/lib/python3.10/site-packages/airflow/operators/python.py", line 181, in execute
    return_value = self.execute_callable()
  File "/home/gabi/Documentos/Gabi/Indicium/code-challenge-indicium/ind_env/lib/python3.10/site-packages/airflow/operators/python.py", line 198, in execute_callable
    return self.python_callable(*self.op_args, **self.op_kwargs)
  File "/home/gabi/Documentos/Gabi/Indicium/code-challenge-indicium/dags/LH_ED_GABRIELLEMUNIZ.py", line 82, in write_second_db
    combined_data.to_sql(f'table', con_db, if_exists = "replace", index = False)
  File "/home/gabi/Documentos/Gabi/Indicium/code-challenge-indicium/ind_env/lib/python3.10/site-packages/pandas/core/generic.py", line 2878, in to_sql
    return sql.to_sql(
  File "/home/gabi/Documentos/Gabi/Indicium/code-challenge-indicium/ind_env/lib/python3.10/site-packages/pandas/io/sql.py", line 769, in to_sql
    return pandas_sql.to_sql(
  File "/home/gabi/Documentos/Gabi/Indicium/code-challenge-indicium/ind_env/lib/python3.10/site-packages/pandas/io/sql.py", line 2378, in to_sql
    table.create()
  File "/home/gabi/Documentos/Gabi/Indicium/code-challenge-indicium/ind_env/lib/python3.10/site-packages/pandas/io/sql.py", line 903, in create
    if self.exists():
  File "/home/gabi/Documentos/Gabi/Indicium/code-challenge-indicium/ind_env/lib/python3.10/site-packages/pandas/io/sql.py", line 889, in exists
    return self.pd_sql.has_table(self.name, self.schema)
  File "/home/gabi/Documentos/Gabi/Indicium/code-challenge-indicium/ind_env/lib/python3.10/site-packages/pandas/io/sql.py", line 2385, in has_table
    return len(self.execute(query, [name]).fetchall()) > 0
  File "/home/gabi/Documentos/Gabi/Indicium/code-challenge-indicium/ind_env/lib/python3.10/site-packages/pandas/io/sql.py", line 2214, in execute
    raise ex from exc
pandas.errors.DatabaseError: Execution failed on sql 'SELECT name FROM sqlite_master WHERE type='table' AND name=?;': syntax error at or near ";"
LINE 1: ...ELECT name FROM sqlite_master WHERE type='table' AND name=?;
                                                                      ^

[2023-07-25T20:16:15.882-0300] {taskinstance.py:1345} INFO - Marking task as UP_FOR_RETRY. dag_id=LH_ED_GABRIELLEMUNIZ, task_id=write_second_db, execution_date=20230725T134500, start_date=20230725T231615, end_date=20230725T231615
[2023-07-25T20:16:15.901-0300] {standard_task_runner.py:104} ERROR - Failed to execute job 259 for task write_second_db (Execution failed on sql 'SELECT name FROM sqlite_master WHERE type='table' AND name=?;': syntax error at or near ";"
LINE 1: ...ELECT name FROM sqlite_master WHERE type='table' AND name=?;
                                                                      ^
; 150074)
[2023-07-25T20:16:15.931-0300] {local_task_job_runner.py:225} INFO - Task exited with return code 1
[2023-07-25T20:16:15.949-0300] {taskinstance.py:2653} INFO - 0 downstream tasks scheduled from follow-on schedule check
