[2023-07-25T23:16:18.216-0300] {taskinstance.py:1103} INFO - Dependencies all met for dep_context=non-requeueable deps ti=<TaskInstance: LH_ED_GABRIELLEMUNIZ.write_second_db scheduled__2023-07-25T13:45:00+00:00 [queued]>
[2023-07-25T23:16:18.224-0300] {taskinstance.py:1103} INFO - Dependencies all met for dep_context=requeueable deps ti=<TaskInstance: LH_ED_GABRIELLEMUNIZ.write_second_db scheduled__2023-07-25T13:45:00+00:00 [queued]>
[2023-07-25T23:16:18.224-0300] {taskinstance.py:1308} INFO - Starting attempt 77 of 80
[2023-07-25T23:16:18.245-0300] {taskinstance.py:1327} INFO - Executing <Task(PythonOperator): write_second_db> on 2023-07-25 13:45:00+00:00
[2023-07-25T23:16:18.252-0300] {standard_task_runner.py:57} INFO - Started process 192858 to run task
[2023-07-25T23:16:18.255-0300] {standard_task_runner.py:84} INFO - Running: ['airflow', 'tasks', 'run', 'LH_ED_GABRIELLEMUNIZ', 'write_second_db', 'scheduled__2023-07-25T13:45:00+00:00', '--job-id', '337', '--raw', '--subdir', 'DAGS_FOLDER/LH_ED_GABRIELLEMUNIZ.py', '--cfg-path', '/tmp/tmppakg5i3u']
[2023-07-25T23:16:18.256-0300] {standard_task_runner.py:85} INFO - Job 337: Subtask write_second_db
[2023-07-25T23:16:18.307-0300] {task_command.py:410} INFO - Running <TaskInstance: LH_ED_GABRIELLEMUNIZ.write_second_db scheduled__2023-07-25T13:45:00+00:00 [running]> on host ubuntu
[2023-07-25T23:16:18.380-0300] {taskinstance.py:1545} INFO - Exporting env vars: AIRFLOW_CTX_DAG_OWNER='gabi' AIRFLOW_CTX_DAG_ID='LH_ED_GABRIELLEMUNIZ' AIRFLOW_CTX_TASK_ID='write_second_db' AIRFLOW_CTX_EXECUTION_DATE='2023-07-25T13:45:00+00:00' AIRFLOW_CTX_TRY_NUMBER='77' AIRFLOW_CTX_DAG_RUN_ID='scheduled__2023-07-25T13:45:00+00:00'
[2023-07-25T23:16:18.392-0300] {logging_mixin.py:150} WARNING - /home/gabi/Documentos/Gabi/Indicium/code-challenge-indicium/ind_env/lib/python3.10/site-packages/airflow/utils/context.py:313 AirflowContextDeprecationWarning: Accessing 'execution_date' from the template is deprecated and will be removed in a future version. Please use 'data_interval_start' or 'logical_date' instead.
[2023-07-25T23:16:19.169-0300] {taskinstance.py:1824} ERROR - Task failed with exception
Traceback (most recent call last):
  File "/home/gabi/Documentos/Gabi/Indicium/code-challenge-indicium/ind_env/lib/python3.10/site-packages/airflow/operators/python.py", line 181, in execute
    return_value = self.execute_callable()
  File "/home/gabi/Documentos/Gabi/Indicium/code-challenge-indicium/ind_env/lib/python3.10/site-packages/airflow/operators/python.py", line 198, in execute_callable
    return self.python_callable(*self.op_args, **self.op_kwargs)
  File "/home/gabi/Documentos/Gabi/Indicium/code-challenge-indicium/dags/LH_ED_GABRIELLEMUNIZ.py", line 95, in write_second_db
    final_query()
  File "/home/gabi/Documentos/Gabi/Indicium/code-challenge-indicium/dags/LH_ED_GABRIELLEMUNIZ.py", line 112, in final_query
    df.to_csv(file_path, index = False)
NameError: name 'file_path' is not defined
[2023-07-25T23:16:19.182-0300] {taskinstance.py:1345} INFO - Marking task as UP_FOR_RETRY. dag_id=LH_ED_GABRIELLEMUNIZ, task_id=write_second_db, execution_date=20230725T134500, start_date=20230726T021618, end_date=20230726T021619
[2023-07-25T23:16:19.201-0300] {standard_task_runner.py:104} ERROR - Failed to execute job 337 for task write_second_db (name 'file_path' is not defined; 192858)
[2023-07-25T23:16:19.230-0300] {local_task_job_runner.py:225} INFO - Task exited with return code 1
[2023-07-25T23:16:19.281-0300] {taskinstance.py:2653} INFO - 0 downstream tasks scheduled from follow-on schedule check
