[2023-07-24T19:00:12.593-0300] {taskinstance.py:1103} INFO - Dependencies all met for dep_context=non-requeueable deps ti=<TaskInstance: LH_ED_GABRIELLEMUNIZ.extract_write_local scheduled__2023-07-24T20:20:00+00:00 [queued]>
[2023-07-24T19:00:12.599-0300] {taskinstance.py:1103} INFO - Dependencies all met for dep_context=requeueable deps ti=<TaskInstance: LH_ED_GABRIELLEMUNIZ.extract_write_local scheduled__2023-07-24T20:20:00+00:00 [queued]>
[2023-07-24T19:00:12.600-0300] {taskinstance.py:1308} INFO - Starting attempt 11 of 14
[2023-07-24T19:00:12.619-0300] {taskinstance.py:1327} INFO - Executing <Task(PythonOperator): extract_write_local> on 2023-07-24 20:20:00+00:00
[2023-07-24T19:00:12.623-0300] {standard_task_runner.py:57} INFO - Started process 21640 to run task
[2023-07-24T19:00:12.627-0300] {standard_task_runner.py:84} INFO - Running: ['airflow', 'tasks', 'run', 'LH_ED_GABRIELLEMUNIZ', 'extract_write_local', 'scheduled__2023-07-24T20:20:00+00:00', '--job-id', '24', '--raw', '--subdir', 'DAGS_FOLDER/LH_ED_GABRIELLEMUNIZ.py', '--cfg-path', '/tmp/tmp2efzw8xd']
[2023-07-24T19:00:12.627-0300] {standard_task_runner.py:85} INFO - Job 24: Subtask extract_write_local
[2023-07-24T19:00:12.681-0300] {task_command.py:410} INFO - Running <TaskInstance: LH_ED_GABRIELLEMUNIZ.extract_write_local scheduled__2023-07-24T20:20:00+00:00 [running]> on host ubuntu
[2023-07-24T19:00:12.762-0300] {taskinstance.py:1545} INFO - Exporting env vars: AIRFLOW_CTX_DAG_OWNER='gabi' AIRFLOW_CTX_DAG_ID='LH_ED_GABRIELLEMUNIZ' AIRFLOW_CTX_TASK_ID='extract_write_local' AIRFLOW_CTX_EXECUTION_DATE='2023-07-24T20:20:00+00:00' AIRFLOW_CTX_TRY_NUMBER='11' AIRFLOW_CTX_DAG_RUN_ID='scheduled__2023-07-24T20:20:00+00:00'
[2023-07-24T19:00:12.788-0300] {taskinstance.py:1824} ERROR - Task failed with exception
Traceback (most recent call last):
  File "/home/gabi/Documentos/Gabi/Indicium/code-challenge-indicium/ind_env/lib/python3.10/site-packages/airflow/operators/python.py", line 181, in execute
    return_value = self.execute_callable()
  File "/home/gabi/Documentos/Gabi/Indicium/code-challenge-indicium/ind_env/lib/python3.10/site-packages/airflow/operators/python.py", line 198, in execute_callable
    return self.python_callable(*self.op_args, **self.op_kwargs)
  File "/home/gabi/Documentos/Gabi/Indicium/code-challenge-indicium/dags/LH_ED_GABRIELLEMUNIZ.py", line 56, in extract_write_local
    extract_write_postgres()
  File "/home/gabi/Documentos/Gabi/Indicium/code-challenge-indicium/dags/LH_ED_GABRIELLEMUNIZ.py", line 27, in extract_write_postgres
    con = psycopg2.connect(
  File "/home/gabi/Documentos/Gabi/Indicium/code-challenge-indicium/ind_env/lib/python3.10/site-packages/psycopg2/__init__.py", line 122, in connect
    conn = _connect(dsn, connection_factory=connection_factory, **kwasync)
psycopg2.OperationalError: connection to server at "localhost" (127.0.0.1), port 5432 failed: FATAL:  password authentication failed for user "northwind_user"
connection to server at "localhost" (127.0.0.1), port 5432 failed: FATAL:  password authentication failed for user "northwind_user"

[2023-07-24T19:00:12.794-0300] {taskinstance.py:1345} INFO - Marking task as UP_FOR_RETRY. dag_id=LH_ED_GABRIELLEMUNIZ, task_id=extract_write_local, execution_date=20230724T202000, start_date=20230724T220012, end_date=20230724T220012
[2023-07-24T19:00:12.809-0300] {standard_task_runner.py:104} ERROR - Failed to execute job 24 for task extract_write_local (connection to server at "localhost" (127.0.0.1), port 5432 failed: FATAL:  password authentication failed for user "northwind_user"
connection to server at "localhost" (127.0.0.1), port 5432 failed: FATAL:  password authentication failed for user "northwind_user"
; 21640)
[2023-07-24T19:00:12.838-0300] {local_task_job_runner.py:225} INFO - Task exited with return code 1
[2023-07-24T19:00:12.864-0300] {taskinstance.py:2653} INFO - 0 downstream tasks scheduled from follow-on schedule check
